Workbook
Name ListUnits: Lists!$A$7:$A$32
Name ListRoles: Lists!$B$7:$B$32
Name ListCategories: Lists!$C$7:$C$32
Name ListYesNo: Lists!$D$7:$D$8
Name ListDirections: Lists!$E$7:$E$8
Name ListMainGroups: OFFSET(MainGroups!$B$7,0,0,MAX(COUNTIF(MainGroups!$B$7:$B$16,"?*"),1),1)
Name ListBaskets: OFFSET(Baskets!$E$7,0,0,MAX(COUNTIF(Baskets!$E$7:$E$36,"?*"),1),1)
Name ListWorkGroups: OFFSET(WorkGroups!$B$7,0,0,MAX(COUNTIF(WorkGroups!$B$7:$B$36,"?*"),1),1)
Name ListBankCodes: OFFSET(Banks!$A$7,0,0,MAX(COUNTIF(Banks!$A$7:$A$16,"?*"),1),1)

Sheet Home
A1: مازندشت — سورتینگ و بسته‌بندی مرکبات
A2: باغدشت، بخش مرکزی، شهرستان قائم‌شهر، استان مازندران، ایران | MAZANDASHT · CITRUS SORTING & PACKING
A3: فایل مادر (INFO) — مرکز تعریف داده‌های سامانه مازندشت
A5: آمار ثبت‌شده‌ها (خودکار):
A6: بانک‌ها | C6: کل حساب‌ها | E6: مشتریان | G6: فروشندگان
A7: =COUNTA(Banks!$B$7:$B$16) | C7: =COUNTIF(Accounts!$D$7:$D$566,"?*") | E7: =COUNTIFS(Accounts!$B$7:$B$566,"مشتری",Accounts!$D$7:$D$566,"?*") | G7: =COUNTIFS(Accounts!$B$7:$B$566,"فروشنده",Accounts!$D$7:$D$566,"?*")
A8: تأمین‌کنندگان | C8: کارکنان | E8: سایر حساب‌ها | G8: دارایی‌های ثابت
A9: =COUNTIFS(Accounts!$B$7:$B$566,"تأمین‌کننده",Accounts!$D$7:$D$566,"?*") | C9: =COUNTIFS(Accounts!$B$7:$B$566,"کارمند",Accounts!$D$7:$D$566,"?*") | E9: =COUNTIFS(Accounts!$B$7:$B$566,"سایر حساب",Accounts!$D$7:$D$566,"?*") | G9: =COUNTIFS(Accounts!$B$7:$B$566,"دارایی ثابت",Accounts!$D$7:$D$566,"?*")
A10: وام‌ها | C10: سرمایه و آورده | E10: عملیات باسکول | G10: محصولات خرید
A11: =COUNTIFS(Accounts!$B$7:$B$566,"وام و تسهیلات",Accounts!$D$7:$D$566,"?*") | C11: =COUNTIFS(Accounts!$B$7:$B$566,"سرمایه و آورده صاحبان",Accounts!$D$7:$D$566,"?*") | E11: =COUNTA(Ops!$B$7:$B$26) | G11: =COUNTA(Products_Buy!$B$7:$B$106)
A12: محصولات فروش | C12: انبارها | E12: گروه‌های کاری | G12: چک‌های تعریف‌شده
A13: =COUNTA(Products_Sell!$B$7:$B$106) | C13: =COUNTA(Warehouses!$B$7:$B$21) | E13: =COUNTA(WorkGroups!$B$7:$B$36) | G13: =COUNTA(Cheques!$A$7:$A$506)
A15: فهرست شیت‌های این فایل
A16: Company | B16: مشخصات شرکت — منبع سرصفحه همه فایل‌ها
A17: Params | B17: پارامترهای محاسباتی (P01 وزن سبد، P02 درصد افت و…) — منبع فرمول‌های فایل خرید
A18: Groups | B18: ماهیت حساب‌ها و زیرمجموعه‌هایشان — منبع کشوهای آبشاری شیت Accounts
A19: MainGroups / SubGroups | B19: گروه‌های اصلی تراکنش (G…) و زیرگروه‌هایشان (SG…) — قابل توسعه
A20: WorkGroups | B20: گروه‌های کاری (گنگ دستمزد) — کد WG…
A21: Accounts | B21: دفتر حساب‌ها — همه صاحبان حساب یکجا: کد + ماهیت + زیرمجموعه + مشخصات
A22: Banks | B22: بانک‌ها — کد، عنوان روزمره، مانده اولیه، فعال بودن
A23: Cheques | B23: دفتر چک‌های پرداختی — تعریف شماره چک‌ها (بانک/شعبه/دفترچه/سری/صیاد اطلاعاتی)
A24: TxnTypes | B24: انواع تراکنش پولی — قابل توسعه برای ماهیت‌های آینده
A25: Ops | B25: انواع عملیات باسکول — جهت (ورود/خروج) و طبقه (خرید/فروش/مرجوعی/انتقال)
A26: Products_Buy | B26: محصولات خرید — کد PB…
A27: Products_Sell | B27: محصولات فروش — کد PS… (با نوع سبد و نوع مرکبات)
... A32: Help | B32: راهنمای کل سامانه — نقشه فایل‌ها، جریان داده و قواعد
A35: قواعد کدگذاری (در همه فایل‌ها یکسان است)
A36: موضوع | C36: قالب کد | F36: نکته
A37: حساب‌ها (یکجا) | C37: C… / SL… / S… / E… / X… | F37: همه در شیت Accounts — با ماهیت و زیرمجموعه کشویی آبشاری
A38: بانک‌ها | C38: BANK01 … BANK10 | F38: کد ثابت — عنوان آزاد
A39: انواع تراکنش | C39: T01 …
A40: محصولات خرید / فروش | C40: PB01… / PS01… | F40: محصول فروش: نوع سبد + نوع مرکبات دارد
A41: سبدها / انبارها | C41: BK01… / W01…
A42: پارامترها | C42: P01, P02, … | F42: وزن سبد، درصد افت و…
A44: قواعد طلایی
A45: ۱) هرگز کدها را تغییر ندهید؛ عنوان‌ها را آزادانه عوض کنید (سیستم با «کد» کار می‌کند، نه با عنوان).
A46: ۲) ردیف تازه = ردیف خالی آماده بعدی؛ کدها از قبل درج شده‌اند. بین ردیف‌ها ردیف خالی نگذارید.
A47: ۳) برای حذف، محتوای سلول‌ها را پاک کنید (Delete) — خودِ ردیف را حذف نکنید.
A48: ۴) این فایل و فایل تراکنش‌ها همیشه باید در یک پوشه باشند؛ مسیر لینک نسبی است.
A49: ۵) بعد از تغییر در این فایل، در فایل تراکنش‌ها: Data ← Edit Links ← Update Values.
...

Sheet Company
A1: مازندشت — سورتینگ و بسته‌بندی مرکبات
A2: باغدشت، بخش مرکزی، شهرستان قائم‌شهر، استان مازندران، ایران | MAZANDASHT · CITRUS SORTING & PACKING
A3: مشخصات شرکت (به‌صورت خودکار در سرصفحه فایل‌های دیگر درج می‌شود)
B5: شرکت سورتینگ و بسته‌بندی مرکبات مازندشت (مدیریت قاسم زاهدی) | C5: شرکت سورتینگ و بسته‌بندی مرکبات مازندشت | H5: جای لوگو (Insert ← Picture)
B6: برند | C6: مازندشت
B7: زمینه فعالیت | C7: سورتینگ، بسته‌بندی و بازرگانی مرکبات
B8: نشانی | C8: باغدشت، بخش مرکزی، شهرستان قائم‌شهر، استان مازندران، ایران
B9: تلفن ثابت | C9: 011-00000000
B10: تلفن همراه | C10: 0911-0000000
B11: قاسم زاهدی | C11: (نام مدیرعامل)
B12: سال مالی | C12: 1405
B13: واحد پول | C13: ریال
B14: یادداشت | C14: این اطلاعات به‌صورت خودکار در سرصفحه فایل‌های دیگر تکرار می‌شود.

Sheet Params
A1: مازندشت — سورتینگ و بسته‌بندی مرکبات
A2: باغدشت، بخش مرکزی، شهرستان قائم‌شهر، استان مازندران، ایران
A3: پارامترهای محاسباتی — منبع فرمول‌های فایل‌های دیگر
A4: مقادیر زردرنگ را آزادانه تغییر دهید (مثلاً وزن هر سبد یا درصد افت) — فایل خرید مرکبات خودکار از همین‌ها می‌خواند. کدها را تغییر ندهید؛ ردیف‌های بعدی برای پارامترهای آینده آزادند.
A5: کد | B5: نام پارامتر | C5: مقدار | D5: واحد | E5: توضیح
A6: Code | B6: Parameter | C6: Value | D6: Unit | E6: Note
A7: P01 | B7: وزن هر سبد (تار) | C7: 1.5 | D7: کیلوگرم | E7: در محاسبه وزن خالص خرید مرکبات کسر می‌شود
A8: P02 | B8: درصد افت | C8: 1 | D8: درصد | E8: از وزن خالص خرید کسر می‌شود
A9: P03
A10: P04
A11: P05
A12: P06
A13: P07
A14: P08
A15: P09
A16: P10
A17: P11
A18: P12

Sheet Groups
A1: مازندشت — سورتینگ و بسته‌بندی مرکبات
A2: باغدشت، بخش مرکزی، شهرستان قائم‌شهر، استان مازندران، ایران | MAZANDASHT · CITRUS SORTING & PACKING
A3: گروه‌بندی حساب‌ها — ماهیت‌ها، زیرمجموعه‌ها و گروه‌های حسابداری/حسابرسی
A4: هشت ستون اول = ماهیت حساب‌ها (مشتری، فروشنده، تأمین‌کننده، کارمند، سایر، دارایی ثابت، وام و تسهیلات، سرمایه و آورده صاحبان) و زیرشان زیرمجموعه‌های هر ماهیت — منبع کشوهای آبشاری شیت Accounts. ستون‌های «گروه حسابداری» و «گروه حسابرسی» برای گزارش‌های حسابداری و حسابرسی‌اند و در شیت Accounts به‌صورت کشویی انتخاب می‌شوند. مقدار جدید = در اولین سلول خالی همان ستون بنویسید (ترتیب ستون‌های ماهیت = ترتیب دسته‌بندی خلاصه فایل خرید). ماهیت‌ها را جابه‌جا یا حذف نکنید؛ افزودن آزاد است.
A6: مشتری | B6: فروشنده | C6: تأمین‌کننده | D6: کارمند | E6: سایر حساب | F6: دارایی ثابت | G6: وام و تسهیلات | H6: سرمایه و آورده صاحبان | I6: گروه حسابداری | J6: گروه حسابرسی
A7: عمده | B7: حجره‌دار میدان بار | C7: باغ‌دار | D7: مدیرعامل | E7: حساب اداری/داخلی | F7: زمین و ساختمان | G7: وام بانکی | H7: سرمایه اولیه و آورده نقدی | I7: کلیدی | J7: پایش کامل
A8: صادراتی | B8: صادراتی | C8: حجره‌دار میدان بار | D8: حسابدار | E8: کارمزد بانکی | F8: خودرو و حمل‌ونقل | G8: تسهیلات و اعتبارات | H8: برداشت سرمایه | I8: عادی | J8: نمونه‌ای
A9: خرده‌فروش | B9: واسطه | C9: عامل خرید | D9: فروشنده | E9: مالیات | F9: ماشین‌آلات و تجهیزات | G9: قرض از اشخاص | I9: موقت | J9: معاف
A10: نقدی | B10: نقدی | C10: فروشنده سبد | D10: انباردار | E10: صندوق
A11: حجره‌دار میدان بار تهران | C11: متفرقه | D11: سرپرست خط | E11: متفرقه
A12: حجره‌دار میدان بار بابل | C12: باغ‌دار تامسون | D12: کارگر
A13: صادراتی خزر | C13: باغ‌دار نارنگی
C14: باغ‌دار پرتقال خونی
C15: خرید سردرختی
C16: باغدار لیمو سنگی

Sheet MainGroups
A1: مازندشت — سورتینگ و بسته‌بندی مرکبات
A2: باغدشت، بخش مرکزی، شهرستان قائم‌شهر، استان مازندران، ایران
A3: گروه‌های اصلی تراکنش‌ها — خرید / فروش / هزینه / شخصی
A4: گروه اصلی، ماهیت کلی تراکنش را مشخص می‌کند و در فایل تراکنش‌ها و گزارش‌ها (فروش، خرید، هزینه‌ها) استفاده می‌شود. گروه جدید = ردیف خالی بعدی (کد G… از قبل درج شده). کدها را تغییر ندهید.
A5: کد | B5: عنوان گروه | C5: توضیحات
A6: Code | B6: Group | C6: Notes
A7: G01 | B7: خرید | C7: خرید کالا و مرکبات
A8: G02 | B8: فروش | C8: فروش کالا و مرکبات
A9: G03 | B9: هزینه | C9: هزینه‌های عملیاتی شرکت
A10: G04 | B10: شخصی قاسم | C10: تراکنش‌های شخصی مدیریت — خارج از محاسبات درآمدی و ترازنامه‌ای شرکت
A11: G05 | B11: وام و تسهیلات | C11: دریافت وام / پرداخت اقساط — طرف حساب = حساب وام L… (بهره: گروه هزینه)
A12: G06 | B12: سرمایه و آورده | C12: آورده / برداشت صاحب سرمایه — طرف حساب = CAP… (در حقوق ترازنامه)
A13: G07 | B13: دارایی ثابت | C13: خرید / فروش زمین، خودرو، تجهیزات — طرف حساب = F… (در دارایی ترازنامه)
A14: G08
A15: G09
A16: G10

Sheet SubGroups
A1: مازندشت — سورتینگ و بسته‌بندی مرکبات
A2: باغدشت، بخش مرکزی، شهرستان قائم‌شهر، استان مازندران، ایران
A3: زیرگروه‌های تراکنش‌ها — قابل توسعه (مثلاً انواع هزینه)
A4: هر زیرگروه به یک گروه اصلی وصل است (کشویی). در فایل تراکنش‌ها پس از انتخاب گروه، زیرگروه به‌صورت آبشاری ظاهر می‌شود. زیرگروه جدید = ردیف خالی بعدی (کد SG… از قبل درج شده)؛ ابتدا گروه را انتخاب کنید، بعد عنوان را بنویسید.
A5: کد | B5: گروه اصلی | C5: عنوان زیرگروه | D5: توضیحات
A6: Code | B6: Main Group | C6: Subgroup | D6: Notes
A7: SG001 | B7: هزینه | C7: مواد غذایی | D7: خوراک سالن و پرسنل
A8: SG002 | B8: هزینه | C8: دستمزد کارکنان
A9: SG003 | B9: هزینه | C9: بهره و کارمزد وام | D9: اقساط بهره و کارمزد وام‌ها — اصل وام حساب L… دارد
A10: SG004 | B10: هزینه | C10: رنگ و واکس | D10: مواد مصرفی بسته‌بندی
A11: SG005 | B11: هزینه | C11: کارمزد بانکی
A12: SG006
A13: SG007
A14: SG008
A15: SG009
A16: SG010
A17: SG011
A18: SG012
A19: SG013
A20: SG014
A21: SG015
A22: SG016
A23: SG017
... A106: SG100

Sheet WorkGroups
A1: مازندشت — سورتینگ و بسته‌بندی مرکبات
A2: باغدشت، بخش مرکزی، شهرستان قائم‌شهر، استان مازندران، ایران
A3: گروه‌های کاری (گنگ‌های دستمزد)
A4: گروه کاری = گنگی که دستمزدش یک‌جا تعلق می‌گیرد. کدها از WG01 شروع می‌شوند. اعضای هر گروه را در شیت Staff با ستون «گروه کاری» تعیین کنید؛ ریز تقسیم دستمزد گروهی در فایل کارکنان (Employees.xlsx ← شیت Shares) وارد می‌شود.
A5: کد | B5: عنوان گروه کاری | C5: توضیحات
A6: Code | B6: Work Group | C6: Notes
A7: WG01 | B7: گروه سالن ۱ | C7: خط سورتینگ — شیفت صبح
A8: WG02 | B8: گروه بسته‌بندی
A9: WG03 | B9: گروه باربری
A10: WG04
A11: WG05
A12: WG06
A13: WG07
A14: WG08
A15: WG09
A16: WG10
A17: WG11
A18: WG12
A19: WG13
A20: WG14
A21: WG15
... A36: WG30

Sheet Staff
A1: مازندشت — سورتینگ و بسته‌بندی مرکبات
A2: باغدشت، بخش مرکزی، شهرستان قائم‌شهر، استان مازندران، ایران
A3: کارکنان — مشخصات تکمیلی (حساب‌های E…)
A4: کدها همان حساب‌های E… شیت Accounts هستند؛ نام را آنجا بنویسید — اینجا خودکار می‌آید. «گروه کاری» را انتخاب کنید تا در گزارش‌های دستمزد گروهی استفاده شود. ردیف بدون نام در Accounts، خالی محسوب می‌شود.
A5: کد کارمند | B5: نام (خودکار) | C5: گروه کاری | D5: سمت | E5: شماره کارت / شبا | F5: توضیحات
A6: Code | B6: Name (auto) | C6: Work Group | D6: Role | E6: Card / Sheba | F6: Notes
A7: E001 | B7: =IF($A7="","",IFERROR(IF(VLOOKUP($A7,Accounts!$A$7:$D$566,4,0)="","—",VLOOKUP($A7,Accounts!$A$7:$D$566,4,0)),"—")) | D7: مدیرعامل
A8: E002 | B8: =IF($A8="","",IFERROR(IF(VLOOKUP($A8,Accounts!$A$7:$D$566,4,0)="","—",VLOOKUP($A8,Accounts!$A$7:$D$566,4,0)),"—")) | D8: حسابدار
A9: E003 | B9: =IF($A9="","",IFERROR(IF(VLOOKUP($A9,Accounts!$A$7:$D$566,4,0)="","—",VLOOKUP($A9,Accounts!$A$7:$D$566,4,0)),"—")) | D9: فروشنده / بازاریاب
A10: E004 | B10: =IF($A10="","",IFERROR(IF(VLOOKUP($A10,Accounts!$A$7:$D$566,4,0)="","—",VLOOKUP($A10,Accounts!$A$7:$D$566,4,0)),"—")) | D10: انباردار
A11: E005 | B11: =IF($A11="","",IFERROR(IF(VLOOKUP($A11,Accounts!$A$7:$D$566,4,0)="","—",VLOOKUP($A11,Accounts!$A$7:$D$566,4,0)),"—")) | C11: WG01 | D11: سرپرست خط | E11: 6037-****-****-01 (نمونه)
A12: E006 | B12: =IF($A12="","",IFERROR(IF(VLOOKUP($A12,Accounts!$A$7:$D$566,4,0)="","—",VLOOKUP($A12,Accounts!$A$7:$D$566,4,0)),"—")) | C12: WG01 | D12: کارگر | E12: 6037-****-****-02 (نمونه)
A13: E007 | B13: =IF($A13="","",IFERROR(IF(VLOOKUP($A13,Accounts!$A$7:$D$566,4,0)="","—",VLOOKUP($A13,Accounts!$A$7:$D$566,4,0)),"—"))
A14: E008 | B14: =IF($A14="","",IFERROR(IF(VLOOKUP($A14,Accounts!$A$7:$D$566,4,0)="","—",VLOOKUP($A14,Accounts!$A$7:$D$566,4,0)),"—"))
A15: E009 | B15: =IF($A15="","",IFERROR(IF(VLOOKUP($A15,Accounts!$A$7:$D$566,4,0)="","—",VLOOKUP($A15,Accounts!$A$7:$D$566,4,0)),"—"))
A16: E010 | B16: =IF($A16="","",IFERROR(IF(VLOOKUP($A16,Accounts!$A$7:$D$566,4,0)="","—",VLOOKUP($A16,Accounts!$A$7:$D$566,4,0)),"—"))
A17: E011 | B17: =IF($A17="","",IFERROR(IF(VLOOKUP($A17,Accounts!$A$7:$D$566,4,0)="","—",VLOOKUP($A17,Accounts!$A$7:$D$566,4,0)),"—"))
A18: E012 | B18: =IF($A18="","",IFERROR(IF(VLOOKUP($A18,Accounts!$A$7:$D$566,4,0)="","—",VLOOKUP($A18,Accounts!$A$7:$D$566,4,0)),"—"))
A19: E013 | B19: =IF($A19="","",IFERROR(IF(VLOOKUP($A19,Accounts!$A$7:$D$566,4,0)="","—",VLOOKUP($A19,Accounts!$A$7:$D$566,4,0)),"—"))
A20: E014 | B20: =IF($A20="","",IFERROR(IF(VLOOKUP($A20,Accounts!$A$7:$D$566,4,0)="","—",VLOOKUP($A20,Accounts!$A$7:$D$566,4,0)),"—"))
A21: E015 | B21: =IF($A21="","",IFERROR(IF(VLOOKUP($A21,Accounts!$A$7:$D$566,4,0)="","—",VLOOKUP($A21,Accounts!$A$7:$D$566,4,0)),"—"))
A22: E016 | B22: =IF($A22="","",IFERROR(IF(VLOOKUP($A22,Accounts!$A$7:$D$566,4,0)="","—",VLOOKUP($A22,Accounts!$A$7:$D$566,4,0)),"—"))
A23: E017 | B23: =IF($A23="","",IFERROR(IF(VLOOKUP($A23,Accounts!$A$7:$D$566,4,0)="","—",VLOOKUP($A23,Accounts!$A$7:$D$566,4,0)),"—"))
A24: E018 | B24: =IF($A24="","",IFERROR(IF(VLOOKUP($A24,Accounts!$A$7:$D$566,4,0)="","—",VLOOKUP($A24,Accounts!$A$7:$D$566,4,0)),"—"))
... A56: E050 | B56: =IF($A56="","",IFERROR(IF(VLOOKUP($A56,Accounts!$A$7:$D$566,4,0)="","—",VLOOKUP($A56,Accounts!$A$7:$D$566,4,0)),"—"))

Sheet Accounts
A1: مازندشت — سورتینگ و بسته‌بندی مرکبات
A2: باغدشت، بخش مرکزی، شهرستان قائم‌شهر، استان مازندران، ایران | MAZANDASHT · CITRUS SORTING & PACKING
A3: دفتر حساب‌ها — همه صاحبان حساب در یکجا (مشتری، فروشنده، تأمین‌کننده، کارمند، سایر، دارایی ثابت، وام، سرمایه)
A4: کدها از قبل به تفکیک پیشوند درج شده‌اند: C… مشتری | SL… فروشنده | S… تأمین‌کننده | E… کارمند | X… سایر حساب | F… دارایی ثابت | L… وام و تسهیلات | CAP… سرمایه و آورده صاحبان. دارایی ثابت/وام/سرمایه در ترازنامه Accounting.xlsx به‌ترتیب در دارایی‌ها، بدهی‌ها و حقوق صاحبان می‌آیند. برای هر حساب: نام را بنویسید، «ماهیت» را از کشویی انتخاب کنید و «زیرمجموعه ماهیت» به‌صورت آبشاری بر اساس ماهیت ظاهر می‌شود. «گروه حسابداری» و «گروه حسابرسی» اختیاری‌اند و برای گزارش‌های حسابداری/حسابرسی استفاده می‌شوند (تعریف مقادیر در شیت Groups). فقط ردیف‌هایی که نام دارند به‌عنوان حساب فعال شمرده می‌شوند.
A5: کد | B5: ماهیت | C5: زیرمجموعه ماهیت | D5: نام صاحب حساب | E5: تلفن | F5: همراه | G5: نشانی | H5: توضیحات | I5: ماهیتِ کد (خودکار) | J5: گروه حسابداری | K5: گروه حسابرسی
A6: Code | B6: Nature | C6: Subgroup | D6: Account Holder | E6: Phone | F6: Mobile | G6: Address | H6: Notes | I6: Code Nature | J6: Accounting Group | K6: Audit Group
A7: C001 | B7: مشتری | C7: عمده | D7: علی محمدی (میدان بار بابل) | E7: 011-33330001 | F7: 09110000001 | G7: بابل — میدان مرکبات | H7: مشتری کلیدی پرتقال تامسون | I7: =IF($A7="","",IF(LEFT(UPPER(TRIM($A7)),2)="SL","فروشنده",IF(LEFT(UPPER(TRIM($A7)),3)="CAP","سرمایه و آورده صاحبان",IF(LEFT(UPPER(TRIM($A7)),1)="F","دارایی ثابت",IF(LEFT(UPPER(TRIM($A7)),1)="L","وام و تسهیلات",IF(LEFT(UPPER(TRIM($A7)),1)="C","مشتری",IF(LEFT(UPPER(TRIM($A7)),1)="S","تأمین‌کننده",IF(LEFT(UPPER(TRIM($A7)),1)="E","کارمند",IF(LEFT(UPPER(TRIM($A7)),1)="X","سایر حساب",""))))))))) | J7: کلیدی | K7: پایش کامل
A8: C002 | B8: مشتری | C8: صادراتی | D8: شرکت پارس میوه خزر | E8: 011-33330002 | F8: 09110000002 | G8: ساری — شهرک صنعتی | H8: صادرات تامسون به روسیه | I8: =IF($A8="","",IF(LEFT(UPPER(TRIM($A8)),2)="SL","فروشنده",IF(LEFT(UPPER(TRIM($A8)),3)="CAP","سرمایه و آورده صاحبان",IF(LEFT(UPPER(TRIM($A8)),1)="F","دارایی ثابت",IF(LEFT(UPPER(TRIM($A8)),1)="L","وام و تسهیلات",IF(LEFT(UPPER(TRIM($A8)),1)="C","مشتری",IF(LEFT(UPPER(TRIM($A8)),1)="S","تأمین‌کننده",IF(LEFT(UPPER(TRIM($A8)),1)="E","کارمند",IF(LEFT(UPPER(TRIM($A8)),1)="X","سایر حساب",""))))))))) | J8: کلیدی | K8: پایش کامل
A9: C003 | B9: مشتری | C9: خرده‌فروش | D9: فروشگاه میوه بهار | E9: 011-33330003 | F9: 09110000003 | G9: قائم‌شهر — خیابان بابل | H9: فروش نقدی روزمره | I9: =IF($A9="","",IF(LEFT(UPPER(TRIM($A9)),2)="SL","فروشنده",IF(LEFT(UPPER(TRIM($A9)),3)="CAP","سرمایه و آورده صاحبان",IF(LEFT(UPPER(TRIM($A9)),1)="F","دارایی ثابت",IF(LEFT(UPPER(TRIM($A9)),1)="L","وام و تسهیلات",IF(LEFT(UPPER(TRIM($A9)),1)="C","مشتری",IF(LEFT(UPPER(TRIM($A9)),1)="S","تأمین‌کننده",IF(LEFT(UPPER(TRIM($A9)),1)="E","کارمند",IF(LEFT(UPPER(TRIM($A9)),1)="X","سایر حساب",""))))))))) | J9: عادی | K9: نمونه‌ای
A10: C004 | B10: مشتری | C10: عمده | D10: بارفروشی قائم (حاج قاسم صادقی) | E10: 051-33445566 | F10: 09151122334 | G10: مشهد — میدان بار سپاد غرفه ۱۲ | H10: خریدار عمده مرکبات | I10: =IF($A10="","",IF(LEFT(UPPER(TRIM($A10)),2)="SL","فروشنده",IF(LEFT(UPPER(TRIM($A10)),3)="CAP","سرمایه و آورده صاحبان",IF(LEFT(UPPER(TRIM($A10)),1)="F","دارایی ثابت",IF(LEFT(UPPER(TRIM($A10)),1)="L","وام و تسهیلات",IF(LEFT(UPPER(TRIM($A10)),1)="C","مشتری",IF(LEFT(UPPER(TRIM($A10)),1)="S","تأمین‌کننده",IF(LEFT(UPPER(TRIM($A10)),1)="E","کارمند",IF(LEFT(UPPER(TRIM($A10)),1)="X","سایر حساب","")))))))))
A11: C005 | B11: مشتری | C11: صادراتی | D11: بازرگانی خزر مرکبات | E11: 011-42211999 | F11: 09121112233 | G11: آستارا — مرز گمرکی | H11: خریدار نارنگی و پرتقال | I11: =IF($A11="","",IF(LEFT(UPPER(TRIM($A11)),2)="SL","فروشنده",IF(LEFT(UPPER(TRIM($A11)),3)="CAP","سرمایه و آورده صاحبان",IF(LEFT(UPPER(TRIM($A11)),1)="F","دارایی ثابت",IF(LEFT(UPPER(TRIM($A11)),1)="L","وام و تسهیلات",IF(LEFT(UPPER(TRIM($A11)),1)="C","مشتری",IF(LEFT(UPPER(TRIM($A11)),1)="S","تأمین‌کننده",IF(LEFT(UPPER(TRIM($A11)),1)="E","کارمند",IF(LEFT(UPPER(TRIM($A11)),1)="X","سایر حساب","")))))))))
A12: C006 | I12: =IF($A12="","",IF(LEFT(UPPER(TRIM($A12)),2)="SL","فروشنده",IF(LEFT(UPPER(TRIM($A12)),3)="CAP","سرمایه و آورده صاحبان",IF(LEFT(UPPER(TRIM($A12)),1)="F","دارایی ثابت",IF(LEFT(UPPER(TRIM($A12)),1)="L","وام و تسهیلات",IF(LEFT(UPPER(TRIM($A12)),1)="C","مشتری",IF(LEFT(UPPER(TRIM($A12)),1)="S","تأمین‌کننده",IF(LEFT(UPPER(TRIM($A12)),1)="E","کارمند",IF(LEFT(UPPER(TRIM($A12)),1)="X","سایر حساب","")))))))))
A13: C007 | I13: =IF($A13="","",IF(LEFT(UPPER(TRIM($A13)),2)="SL","فروشنده",IF(LEFT(UPPER(TRIM($A13)),3)="CAP","سرمایه و آورده صاحبان",IF(LEFT(UPPER(TRIM($A13)),1)="F","دارایی ثابت",IF(LEFT(UPPER(TRIM($A13)),1)="L","وام و تسهیلات",IF(LEFT(UPPER(TRIM($A13)),1)="C","مشتری",IF(LEFT(UPPER(TRIM($A13)),1)="S","تأمین‌کننده",IF(LEFT(UPPER(TRIM($A13)),1)="E","کارمند",IF(LEFT(UPPER(TRIM($A13)),1)="X","سایر حساب","")))))))))
A14: C008 | I14: =IF($A14="","",IF(LEFT(UPPER(TRIM($A14)),2)="SL","فروشنده",IF(LEFT(UPPER(TRIM($A14)),3)="CAP","سرمایه و آورده صاحبان",IF(LEFT(UPPER(TRIM($A14)),1)="F","دارایی ثابت",IF(LEFT(UPPER(TRIM($A14)),1)="L","وام و تسهیلات",IF(LEFT(UPPER(TRIM($A14)),1)="C","مشتری",IF(LEFT(UPPER(TRIM($A14)),1)="S","تأمین‌کننده",IF(LEFT(UPPER(TRIM($A14)),1)="E","کارمند",IF(LEFT(UPPER(TRIM($A14)),1)="X","سایر حساب","")))))))))
A15: C009 | I15: =IF($A15="","",IF(LEFT(UPPER(TRIM($A15)),2)="SL","فروشنده",IF(LEFT(UPPER(TRIM($A15)),3)="CAP","سرمایه و آورده صاحبان",IF(LEFT(UPPER(TRIM($A15)),1)="F","دارایی ثابت",IF(LEFT(UPPER(TRIM($A15)),1)="L","وام و تسهیلات",IF(LEFT(UPPER(TRIM($A15)),1)="C","مشتری",IF(LEFT(UPPER(TRIM($A15)),1)="S","تأمین‌کننده",IF(LEFT(UPPER(TRIM($A15)),1)="E","کارمند",IF(LEFT(UPPER(TRIM($A15)),1)="X","سایر حساب","")))))))))
A16: C010 | I16: =IF($A16="","",IF(LEFT(UPPER(TRIM($A16)),2)="SL","فروشنده",IF(LEFT(UPPER(TRIM($A16)),3)="CAP","سرمایه و آورده صاحبان",IF(LEFT(UPPER(TRIM($A16)),1)="F","دارایی ثابت",IF(LEFT(UPPER(TRIM($A16)),1)="L","وام و تسهیلات",IF(LEFT(UPPER(TRIM($A16)),1)="C","مشتری",IF(LEFT(UPPER(TRIM($A16)),1)="S","تأمین‌کننده",IF(LEFT(UPPER(TRIM($A16)),1)="E","کارمند",IF(LEFT(UPPER(TRIM($A16)),1)="X","سایر حساب","")))))))))
A17: C011 | I17: =IF($A17="","",IF(LEFT(UPPER(TRIM($A17)),2)="SL","فروشنده",IF(LEFT(UPPER(TRIM($A17)),3)="CAP","سرمایه و آورده صاحبان",IF(LEFT(UPPER(TRIM($A17)),1)="F","دارایی ثابت",IF(LEFT(UPPER(TRIM($A17)),1)="L","وام و تسهیلات",IF(LEFT(UPPER(TRIM($A17)),1)="C","مشتری",IF(LEFT(UPPER(TRIM($A17)),1)="S","تأمین‌کننده",IF(LEFT(UPPER(TRIM($A17)),1)="E","کارمند",IF(LEFT(UPPER(TRIM($A17)),1)="X","سایر حساب","")))))))))
A18: C012 | I18: =IF($A18="","",IF(LEFT(UPPER(TRIM($A18)),2)="SL","فروشنده",IF(LEFT(UPPER(TRIM($A18)),3)="CAP","سرمایه و آورده صاحبان",IF(LEFT(UPPER(TRIM($A18)),1)="F","دارایی ثابت",IF(LEFT(UPPER(TRIM($A18)),1)="L","وام و تسهیلات",IF(LEFT(UPPER(TRIM($A18)),1)="C","مشتری",IF(LEFT(UPPER(TRIM($A18)),1)="S","تأمین‌کننده",IF(LEFT(UPPER(TRIM($A18)),1)="E","کارمند",IF(LEFT(UPPER(TRIM($A18)),1)="X","سایر حساب","")))))))))
A19: C013 | I19: =IF($A19="","",IF(LEFT(UPPER(TRIM($A19)),2)="SL","فروشنده",IF(LEFT(UPPER(TRIM($A19)),3)="CAP","سرمایه و آورده صاحبان",IF(LEFT(UPPER(TRIM($A19)),1)="F","دارایی ثابت",IF(LEFT(UPPER(TRIM($A19)),1)="L","وام و تسهیلات",IF(LEFT(UPPER(TRIM($A19)),1)="C","مشتری",IF(LEFT(UPPER(TRIM($A19)),1)="S","تأمین‌کننده",IF(LEFT(UPPER(TRIM($A19)),1)="E","کارمند",IF(LEFT(UPPER(TRIM($A19)),1)="X","سایر حساب","")))))))))
A20: C014 | I20: =IF($A20="","",IF(LEFT(UPPER(TRIM($A20)),2)="SL","فروشنده",IF(LEFT(UPPER(TRIM($A20)),3)="CAP","سرمایه و آورده صاحبان",IF(LEFT(UPPER(TRIM($A20)),1)="F","دارایی ثابت",IF(LEFT(UPPER(TRIM($A20)),1)="L","وام و تسهیلات",IF(LEFT(UPPER(TRIM($A20)),1)="C","مشتری",IF(LEFT(UPPER(TRIM($A20)),1)="S","تأمین‌کننده",IF(LEFT(UPPER(TRIM($A20)),1)="E","کارمند",IF(LEFT(UPPER(TRIM($A20)),1)="X","سایر حساب","")))))))))
A21: C015 | I21: =IF($A21="","",IF(LEFT(UPPER(TRIM($A21)),2)="SL","فروشنده",IF(LEFT(UPPER(TRIM($A21)),3)="CAP","سرمایه و آورده صاحبان",IF(LEFT(UPPER(TRIM($A21)),1)="F","دارایی ثابت",IF(LEFT(UPPER(TRIM($A21)),1)="L","وام و تسهیلات",IF(LEFT(UPPER(TRIM($A21)),1)="C","مشتری",IF(LEFT(UPPER(TRIM($A21)),1)="S","تأمین‌کننده",IF(LEFT(UPPER(TRIM($A21)),1)="E","کارمند",IF(LEFT(UPPER(TRIM($A21)),1)="X","سایر حساب","")))))))))
A22: C016 | I22: =IF($A22="","",IF(LEFT(UPPER(TRIM($A22)),2)="SL","فروشنده",IF(LEFT(UPPER(TRIM($A22)),3)="CAP","سرمایه و آورده صاحبان",IF(LEFT(UPPER(TRIM($A22)),1)="F","دارایی ثابت",IF(LEFT(UPPER(TRIM($A22)),1)="L","وام و تسهیلات",IF(LEFT(UPPER(TRIM($A22)),1)="C","مشتری",IF(LEFT(UPPER(TRIM($A22)),1)="S","تأمین‌کننده",IF(LEFT(UPPER(TRIM($A22)),1)="E","کارمند",IF(LEFT(UPPER(TRIM($A22)),1)="X","سایر حساب","")))))))))
A23: C017 | I23: =IF($A23="","",IF(LEFT(UPPER(TRIM($A23)),2)="SL","فروشنده",IF(LEFT(UPPER(TRIM($A23)),3)="CAP","سرمایه و آورده صاحبان",IF(LEFT(UPPER(TRIM($A23)),1)="F","دارایی ثابت",IF(LEFT(UPPER(TRIM($A23)),1)="L","وام و تسهیلات",IF(LEFT(UPPER(TRIM($A23)),1)="C","مشتری",IF(LEFT(UPPER(TRIM($A23)),1)="S","تأمین‌کننده",IF(LEFT(UPPER(TRIM($A23)),1)="E","کارمند",IF(LEFT(UPPER(TRIM($A23)),1)="X","سایر حساب","")))))))))
... A206: C200 | I206: =IF($A206="","",IF(LEFT(UPPER(TRIM($A206)),2)="SL","فروشنده",IF(LEFT(UPPER(TRIM($A206)),3)="CAP","سرمایه و آورده صاحبان",IF(LEFT(UPPER(TRIM($A206)),1)="F","دارایی ثابت",IF(LEFT(UPPER(TRIM($A206)),1)="L","وام و تسهیلات",IF(LEFT(UPPER(TRIM($A206)),1)="C","مشتری",IF(LEFT(UPPER(TRIM($A206)),1)="S","تأمین‌کننده",IF(LEFT(UPPER(TRIM($A206)),1)="E","کارمند",IF(LEFT(UPPER(TRIM($A206)),1)="X","سایر حساب","")))))))))
A207: SL001 | B207: فروشنده | C207: حجره‌دار میدان بار | D207: حاج رضا محمدی (نمونه) | E207: 021-55550001 | F207: 09120000001 | G207: تهران — میدان بار میوه و تره‌بار | H207: نمونه | I207: =IF($A207="","",IF(LEFT(UPPER(TRIM($A207)),2)="SL","فروشنده",IF(LEFT(UPPER(TRIM($A207)),3)="CAP","سرمایه و آورده صاحبان",IF(LEFT(UPPER(TRIM($A207)),1)="F","دارایی ثابت",IF(LEFT(UPPER(TRIM($A207)),1)="L","وام و تسهیلات",IF(LEFT(UPPER(TRIM($A207)),1)="C","مشتری",IF(LEFT(UPPER(TRIM($A207)),1)="S","تأمین‌کننده",IF(LEFT(UPPER(TRIM($A207)),1)="E","کارمند",IF(LEFT(UPPER(TRIM($A207)),1)="X","سایر حساب",""))))))))) | J207: کلیدی | K207: پایش کامل
A208: SL002 | B208: فروشنده | C208: صادراتی | D208: شرکت گلسرای شمال (نمونه) | E208: 011-55550002 | F208: 09120000002 | G208: ساری — شهرک صنعتی | H208: نمونه | I208: =IF($A208="","",IF(LEFT(UPPER(TRIM($A208)),2)="SL","فروشنده",IF(LEFT(UPPER(TRIM($A208)),3)="CAP","سرمایه و آورده صاحبان",IF(LEFT(UPPER(TRIM($A208)),1)="F","دارایی ثابت",IF(LEFT(UPPER(TRIM($A208)),1)="L","وام و تسهیلات",IF(LEFT(UPPER(TRIM($A208)),1)="C","مشتری",IF(LEFT(UPPER(TRIM($A208)),1)="S","تأمین‌کننده",IF(LEFT(UPPER(TRIM($A208)),1)="E","کارمند",IF(LEFT(UPPER(TRIM($A208)),1)="X","سایر حساب",""))))))))) | J208: کلیدی | K208: پایش کامل
A209: SL003 | B209: فروشنده | C209: واسطه | D209: عباس نیک‌پی (نمونه) | E209: 011-55550003 | F209: 09120000003 | G209: قائم‌شهر | H209: نمونه | I209: =IF($A209="","",IF(LEFT(UPPER(TRIM($A209)),2)="SL","فروشنده",IF(LEFT(UPPER(TRIM($A209)),3)="CAP","سرمایه و آورده صاحبان",IF(LEFT(UPPER(TRIM($A209)),1)="F","دارایی ثابت",IF(LEFT(UPPER(TRIM($A209)),1)="L","وام و تسهیلات",IF(LEFT(UPPER(TRIM($A209)),1)="C","مشتری",IF(LEFT(UPPER(TRIM($A209)),1)="S","تأمین‌کننده",IF(LEFT(UPPER(TRIM($A209)),1)="E","کارمند",IF(LEFT(UPPER(TRIM($A209)),1)="X","سایر حساب",""))))))))) | J209: عادی | K209: نمونه‌ای
A210: SL004 | B210: فروشنده | C210: نقدی | D210: مشتری نقدی — پاساژ مرکزی (نمونه) | E210: 011-55550004 | F210: 09120000004 | G210: قائم‌شهر — پاساژ مرکزی | H210: نمونه | I210: =IF($A210="","",IF(LEFT(UPPER(TRIM($A210)),2)="SL","فروشنده",IF(LEFT(UPPER(TRIM($A210)),3)="CAP","سرمایه و آورده صاحبان",IF(LEFT(UPPER(TRIM($A210)),1)="F","دارایی ثابت",IF(LEFT(UPPER(TRIM($A210)),1)="L","وام و تسهیلات",IF(LEFT(UPPER(TRIM($A210)),1)="C","مشتری",IF(LEFT(UPPER(TRIM($A210)),1)="S","تأمین‌کننده",IF(LEFT(UPPER(TRIM($A210)),1)="E","کارمند",IF(LEFT(UPPER(TRIM($A210)),1)="X","سایر حساب",""))))))))) | J210: موقت | K210: نمونه‌ای
A211: SL005 | I211: =IF($A211="","",IF(LEFT(UPPER(TRIM($A211)),2)="SL","فروشنده",IF(LEFT(UPPER(TRIM($A211)),3)="CAP","سرمایه و آورده صاحبان",IF(LEFT(UPPER(TRIM($A211)),1)="F","دارایی ثابت",IF(LEFT(UPPER(TRIM($A211)),1)="L","وام و تسهیلات",IF(LEFT(UPPER(TRIM($A211)),1)="C","مشتری",IF(LEFT(UPPER(TRIM($A211)),1)="S","تأمین‌کننده",IF(LEFT(UPPER(TRIM($A211)),1)="E","کارمند",IF(LEFT(UPPER(TRIM($A211)),1)="X","سایر حساب","")))))))))
A212: SL006 | I212: =IF($A212="","",IF(LEFT(UPPER(TRIM($A212)),2)="SL","فروشنده",IF(LEFT(UPPER(TRIM($A212)),3)="CAP","سرمایه و آورده صاحبان",IF(LEFT(UPPER(TRIM($A212)),1)="F","دارایی ثابت",IF(LEFT(UPPER(TRIM($A212)),1)="L","وام و تسهیلات",IF(LEFT(UPPER(TRIM($A212)),1)="C","مشتری",IF(LEFT(UPPER(TRIM($A212)),1)="S","تأمین‌کننده",IF(LEFT(UPPER(TRIM($A212)),1)="E","کارمند",IF(LEFT(UPPER(TRIM($A212)),1)="X","سایر حساب","")))))))))
A213: SL007 | I213: =IF($A213="","",IF(LEFT(UPPER(TRIM($A213)),2)="SL","فروشنده",IF(LEFT(UPPER(TRIM($A213)),3)="CAP","سرمایه و آورده صاحبان",IF(LEFT(UPPER(TRIM($A213)),1)="F","دارایی ثابت",IF(LEFT(UPPER(TRIM($A213)),1)="L","وام و تسهیلات",IF(LEFT(UPPER(TRIM($A213)),1)="C","مشتری",IF(LEFT(UPPER(TRIM($A213)),1)="S","تأمین‌کننده",IF(LEFT(UPPER(TRIM($A213)),1)="E","کارمند",IF(LEFT(UPPER(TRIM($A213)),1)="X","سایر حساب","")))))))))
A214: SL008 | I214: =IF($A214="","",IF(LEFT(UPPER(TRIM($A214)),2)="SL","فروشنده",IF(LEFT(UPPER(TRIM($A214)),3)="CAP","سرمایه و آورده صاحبان",IF(LEFT(UPPER(TRIM($A214)),1)="F","دارایی ثابت",IF(LEFT(UPPER(TRIM($A214)),1)="L","وام و تسهیلات",IF(LEFT(UPPER(TRIM($A214)),1)="C","مشتری",IF(LEFT(UPPER(TRIM($A214)),1)="S","تأمین‌کننده",IF(LEFT(UPPER(TRIM($A214)),1)="E","کارمند",IF(LEFT(UPPER(TRIM($A214)),1)="X","سایر حساب","")))))))))
A215: SL009 | I215: =IF($A215="","",IF(LEFT(UPPER(TRIM($A215)),2)="SL","فروشنده",IF(LEFT(UPPER(TRIM($A215)),3)="CAP","سرمایه و آورده صاحبان",IF(LEFT(UPPER(TRIM($A215)),1)="F","دارایی ثابت",IF(LEFT(UPPER(TRIM($A215)),1)="L","وام و تسهیلات",IF(LEFT(UPPER(TRIM($A215)),1)="C","مشتری",IF(LEFT(UPPER(TRIM($A215)),1)="S","تأمین‌کننده",IF(LEFT(UPPER(TRIM($A215)),1)="E","کارمند",IF(LEFT(UPPER(TRIM($A215)),1)="X","سایر حساب","")))))))))
A216: SL010 | I216: =IF($A216="","",IF(LEFT(UPPER(TRIM($A216)),2)="SL","فروشنده",IF(LEFT(UPPER(TRIM($A216)),3)="CAP","سرمایه و آورده صاحبان",IF(LEFT(UPPER(TRIM($A216)),1)="F","دارایی ثابت",IF(LEFT(UPPER(TRIM($A216)),1)="L","وام و تسهیلات",IF(LEFT(UPPER(TRIM($A216)),1)="C","مشتری",IF(LEFT(UPPER(TRIM($A216)),1)="S","تأمین‌کننده",IF(LEFT(UPPER(TRIM($A216)),1)="E","کارمند",IF(LEFT(UPPER(TRIM($A216)),1)="X","سایر حساب","")))))))))
A217: SL011 | I217: =IF($A217="","",IF(LEFT(UPPER(TRIM($A217)),2)="SL","فروشنده",IF(LEFT(UPPER(TRIM($A217)),3)="CAP","سرمایه و آورده صاحبان",IF(LEFT(UPPER(TRIM($A217)),1)="F","دارایی ثابت",IF(LEFT(UPPER(TRIM($A217)),1)="L","وام و تسهیلات",IF(LEFT(UPPER(TRIM($A217)),1)="C","مشتری",IF(LEFT(UPPER(TRIM($A217)),1)="S","تأمین‌کننده",IF(LEFT(UPPER(TRIM($A217)),1)="E","کارمند",IF(LEFT(UPPER(TRIM($A217)),1)="X","سایر حساب","")))))))))
A218: SL012 | I218: =IF($A218="","",IF(LEFT(UPPER(TRIM($A218)),2)="SL","فروشنده",IF(LEFT(UPPER(TRIM($A218)),3)="CAP","سرمایه و آورده صاحبان",IF(LEFT(UPPER(TRIM($A218)),1)="F","دارایی ثابت",IF(LEFT(UPPER(TRIM($A218)),1)="L","وام و تسهیلات",IF(LEFT(UPPER(TRIM($A218)),1)="C","مشتری",IF(LEFT(UPPER(TRIM($A218)),1)="S","تأمین‌کننده",IF(LEFT(UPPER(TRIM($A218)),1)="E","کارمند",IF(LEFT(UPPER(TRIM($A218)),1)="X","سایر حساب","")))))))))
A219: SL013 | I219: =IF($A219="","",IF(LEFT(UPPER(TRIM($A219)),2)="SL","فروشنده",IF(LEFT(UPPER(TRIM($A219)),3)="CAP","سرمایه و آورده صاحبان",IF(LEFT(UPPER(TRIM($A219)),1)="F","دارایی ثابت",IF(LEFT(UPPER(TRIM($A219)),1)="L","وام و تسهیلات",IF(LEFT(UPPER(TRIM($A219)),1)="C","مشتری",IF(LEFT(UPPER(TRIM($A219)),1)="S","تأمین‌کننده",IF(LEFT(UPPER(TRIM($A219)),1)="E","کارمند",IF(LEFT(UPPER(TRIM($A219)),1)="X","سایر حساب","")))))))))
A220: SL014 | I220: =IF($A220="","",IF(LEFT(UPPER(TRIM($A220)),2)="SL","فروشنده",IF(LEFT(UPPER(TRIM($A220)),3)="CAP","سرمایه و آورده صاحبان",IF(LEFT(UPPER(TRIM($A220)),1)="F","دارایی ثابت",IF(LEFT(UPPER(TRIM($A220)),1)="L","وام و تسهیلات",IF(LEFT(UPPER(TRIM($A220)),1)="C","مشتری",IF(LEFT(UPPER(TRIM($A220)),1)="S","تأمین‌کننده",IF(LEFT(UPPER(TRIM($A220)),1)="E","کارمند",IF(LEFT(UPPER(TRIM($A220)),1)="X","سایر حساب","")))))))))
A221: SL015 | I221: =IF($A221="","",IF(LEFT(UPPER(TRIM($A221)),2)="SL","فروشنده",IF(LEFT(UPPER(TRIM($A221)),3)="CAP","سرمایه و آورده صاحبان",IF(LEFT(UPPER(TRIM($A221)),1)="F","دارایی ثابت",IF(LEFT(UPPER(TRIM($A221)),1)="L","وام و تسهیلات",IF(LEFT(UPPER(TRIM($A221)),1)="C","مشتری",IF(LEFT(UPPER(TRIM($A221)),1)="S","تأمین‌کننده",IF(LEFT(UPPER(TRIM($A221)),1)="E","کارمند",IF(LEFT(UPPER(TRIM($A221)),1)="X","سایر حساب","")))))))))
A222: SL016 | I222: =IF($A222="","",IF(LEFT(UPPER(TRIM($A222)),2)="SL","فروشنده",IF(LEFT(UPPER(TRIM($A222)),3)="CAP","سرمایه و آورده صاحبان",IF(LEFT(UPPER(TRIM($A222)),1)="F","دارایی ثابت",IF(LEFT(UPPER(TRIM($A222)),1)="L","وام و تسهیلات",IF(LEFT(UPPER(TRIM($A222)),1)="C","مشتری",IF(LEFT(UPPER(TRIM($A222)),1)="S","تأمین‌کننده",IF(LEFT(UPPER(TRIM($A222)),1)="E","کارمند",IF(LEFT(UPPER(TRIM($A222)),1)="X","سایر حساب","")))))))))
...

Sheet Banks
A1: مازندشت — سورتینگ و بسته‌بندی مرکبات
A2: باغدشت، بخش مرکزی، شهرستان قائم‌شهر، استان مازندران، ایران
A3: بانک‌ها و حساب‌های شرکت — ۱۰ حساب (کد ثابت، عنوان آزاد)
A4: کد حساب‌ها ثابت است (BANK01 تا BANK10) و در همه فایل‌ها همان است؛ عنوان نمایشی را آزادانه عوض کنید — فایل تراکنش‌ها خودکار به‌روز می‌شود. مشخصات رسمی (شعبه، شماره حساب، شبا و…) در سربرگ هر برگهٔ بانکی در فایل تراکنش‌ها به‌صورت دستی وارد می‌شود.
A5: کد حساب | B5: عنوان نمایشی (روزمره) | C5: مانده اولیه (ریال) | D5: فعال | E5: توضیحات | F5: شماره حساب / شبا
A6: Code | B6: Display Title | C6: Opening Balance | D6: Active | E6: Notes | F6: Account No / IBAN
A7: BANK01 | B7: صادرات 9009 | C7: 0 | D7: بله | E7: حساب جاری صادرات ۹۰۰۹ | F7: 9009
A8: BANK02 | B8: صادرات 2006 | C8: 0 | D8: بله | E8: حساب جاری صادرات ۲۰۰۶ | F8: 2006
A9: BANK03 | B9: بانک سپه | C9: 0 | D9: بله | E9: حساب بانک سپه
A10: BANK04 | B10: بانک مهر ایران | C10: 0 | D10: بله | E10: حساب قرض‌الحسنه مهر ایران
A11: BANK05 | B11: بانک ملت | C11: 0 | D11: بله | E11: حساب بانک ملت
A12: BANK06 | B12: پست بانک | C12: 0 | D12: بله | E12: حساب پست بانک
A13: BANK07 | B13: بانک کشاورزی | C13: 0 | D13: بله | E13: حساب بانک کشاورزی
A14: BANK08 | B14: سایر / ذخیره ۱ | C14: 0 | D14: بله | E14: حساب آزاد
A15: BANK09 | B15: سایر / ذخیره ۲ | C15: 0 | D15: بله | E15: حساب آزاد
A16: BANK10 | B16: صندوق نقدی کارگاه | C16: 0 | D16: بله | E16: صندوق تنخواه کارگاه

Sheet Cheques
A1: مازندشت — سورتینگ و بسته‌بندی مرکبات
A2: باغدشت، بخش مرکزی، شهرستان قائم‌شهر، استان مازندران، ایران
A3: دفتر چک‌های پرداختی — تعریف شماره چک‌ها
A4: هر ردیف = یک برگ چک. شماره چک را دقیقاً مثل خود چک وارد کنید (یکتا)؛ بانک از کشویی. شعبه، دفترچه، سری/سریال و صیاد صرفاً اطلاعاتی‌اند — در گزارش‌ها و فرمول‌ها فقط شماره چک، تاریخ و مبلغ استفاده می‌شود. صدور (تاریخ/مبلغ/ذی‌نفع) در فایل چک‌ها (Cheques.xlsx ← شیت Issues) ثبت می‌شود.
A5: شماره چک | B5: بانک | C5: شعبه | D5: شماره دفترچه | E5: سری / سریال | F5: شناسه صیاد | G5: توضیحات
A6: Cheque No. | B6: Bank | C6: Branch | D6: Cheque Book | E6: Series / Serial | F6: Saiad ID | G6: Notes
B7: BANK01 | C7: شعبه مرکزی قائم‌شهر | D7: د-۴۵۲۱ | E7: سری ۸ / ۷۶۵۴۳۲۱ | F7: ۱۲۳۴۵۶۷۸۹۰۱ | G7: دفترچه جاری شرکت
B8: BANK01 | C8: شعبه مرکزی قائم‌شهر | D8: د-۴۵۲۱ | E8: سری ۸ / ۷۶۵۴۳۲۲ | F8: ۱۲۳۴۵۶۷۸۹۰۲
B9: BANK02 | C9: شعبه بازار | D9: ص-۱۱۸۷ | E9: سری ۳ / ۱۱۲۲۳۳۴ | F9: ۲۰۹۸۷۶۵۴۳۲۱

Sheet TxnTypes
A1: مازندشت — سورتینگ و بسته‌بندی مرکبات
A2: باغدشت، بخش مرکزی، شهرستان قائم‌شهر، استان مازندران، ایران
A3: انواع تراکنش (قابل توسعه برای ماهیت‌های آینده)
A4: ستون نوع تراکنش در Entry فقط اطلاعاتی/تحلیلی است؛ واریز و برداشت از ستون‌های مبلغ خوانده می‌شود. در آینده می‌توانید ماهیت‌های تازه (انتقال، اصلاحیه و…) تعریف کنید.
A5: کد | B5: عنوان | C5: تأثیر بر مانده | D5: توضیح
A6: Code | B6: Title | C6: Balance Effect | D6: Note
A7: T01 | B7: واریز بارفروشان | C7: افزایش مانده | D7: دریافت وجه از خریداران، بارفروشان و حجره‌داران بابت فروش مرکبات (بستانکار شدن مشتری)
A8: T02 | B8: جابه‌جایی بین حساب‌ها | C8: خنثی در مجموع | D8: انتقال داخلی بین حساب‌های شرکت (بدون اثر سود و زیان)
A9: T03 | B9: واریز متفرقه | C9: افزایش مانده | D9: سایر درآمدهای متفرقه، بازیافت ضایعات و...
A10: T04 | B10: سرجمع دستگاه پوز (POS) | C10: افزایش مانده | D10: واریزی سرجمع روزانه کارتخوان‌های سورتینگ و باسکول
A11: T05 | B11: کارمزد و هزینه‌های بانکی | C11: کاهش مانده | D11: هزینه خدمات بانکی، ساتنا، پایا و پیامک (هزینه مالی در سود و زیان)
A12: T06 | B12: وام و تسهیلات دریافتی | C12: افزایش مانده | D12: دریافت تسهیلات و وام بانکی یا قرض تجاری (افزایش بدهی در ترازنامه)
A13: T07 | B13: بازپرداخت وام و تسهیلات | C13: کاهش مانده | D13: پرداخت اقساط اصل و سود وام و تسهیلات
A14: T08 | B14: فروش اموال مدیر (قاسم زاهدی) | C14: افزایش مانده | D14: فروش اموال شخصی مدیر و ورود نقدینگی به چرخه شرکت (افزایش آورده و جاری شرکا در ترازنامه)
A15: T09 | B15: هزینه‌های شخصی مدیر (قاسم زاهدی) | C15: کاهش مانده | D15: پرداخت هزینه‌های شخصی مدیر از حساب شرکت (برداشت جاری شرکا در ترازنامه - عدم انتساب به هزینه شرکت)
A16: T10 | B16: خرید مرکبات / تسویه باغدار | C16: کاهش مانده | D16: پرداخت وجه نقد یا چک به باغداران و تأمین‌کنندگان میوه سردرختی
... A18: T12 | B18: حقوق و دستمزد پرسنل | C18: کاهش مانده | D18: پرداخت دستمزد کارگران سورتینگ، انباردار و حسابدار
A19: T13
A20: T14

Sheet Ops
A1: مازندشت — سورتینگ و بسته‌بندی مرکبات
A2: باغدشت، بخش مرکزی، شهرستان قائم‌شهر، استان مازندران، ایران
A3: انواع عملیات باسکول (ورود/خروج کالا) — قابل توسعه
A4: هر عملیات یک جهت (ورود/خروج) و یک گروه اصلی دارد؛ در دفتر باسکول فقط «عنوان عملیات» را انتخاب می‌کنید و جهت و گروه خودکار می‌آیند. عنوان عملیات باید یکتا باشد. عملیات جدید = ردیف خالی بعدی (کد OP… از قبل درج شده).
A5: کد | B5: عنوان عملیات | C5: جهت | D5: گروه اصلی | E5: توضیحات
A6: Code | B6: Operation | C6: Direction | D6: Main Group | E6: Notes
A7: OP01 | B7: خرید مرکبات | C7: ورود | D7: خرید
A8: OP02 | B8: فروش | C8: خروج | D8: فروش
A9: OP03 | B9: مرجوعی خرید | C9: خروج | D9: خرید
A10: OP04 | B10: مرجوعی فروش | C10: ورود | D10: فروش
A11: OP05 | B11: انتقال به انبار دیگر | C11: خروج
A12: OP06 | B12: انتقال از انبار دیگر | C12: ورود
A13: OP07 | B13: سایر ورود | C13: ورود
A14: OP08 | B14: سایر خروج | C14: خروج
A15: OP09
A16: OP10
A17: OP11
A18: OP12
A19: OP13
A20: OP14
A21: OP15
A22: OP16
A23: OP17
A24: OP18
A25: OP19
A26: OP20

Sheet Products_Buy
A1: مازندشت — سورتینگ و بسته‌بندی مرکبات
A2: باغدشت، بخش مرکزی، شهرستان قائم‌شهر، استان مازندران، ایران
A3: محصولات خرید (ورودی کارخانه)
A4: کدها از PB01 شروع می‌شوند.
A5: کد | B5: نام محصول | C5: دسته | D5: واحد | E5: توضیحات
A6: Code | B6: Product | C6: Category | D6: Unit | E6: Notes
A7: PB01 | B7: پرتقال (عمومی) | C7: پرتقال | D7: کیلوگرم | E7: خرید از باغ/میدان بار
A8: PB02 | B8: نارنگی | C8: نارنگی | D8: کیلوگرم
A9: PB03 | B9: لیمو ترش | C9: لیمو | D9: کیلوگرم
A10: PB04 | B10: گریپ‌فرویت | C10: گریپ‌فرویت | D10: کیلوگرم
A11: PB05
A12: PB06
A13: PB07
A14: PB08
A15: PB09
A16: PB10
A17: PB11
A18: PB12
A19: PB13
A20: PB14
A21: PB15
A22: PB16
... A106: PB100

Sheet Products_Sell
A1: مازندشت — سورتینگ و بسته‌بندی مرکبات
A2: باغدشت، بخش مرکزی، شهرستان قائم‌شهر، استان مازندران، ایران
A3: محصولات فروش (خروجی سورتینگ و بسته‌بندی)
A4: کدها از PS01 شروع می‌شوند. «نوع سبد» را از کشویی انتخاب کنید (از شیت Baskets) — در فایل فروش، با انتخاب هر محصول، نوع سبد و نوع مرکبات آن خودکار نوشته می‌شود.
A5: کد | B5: نام محصول | C5: دسته (نوع مرکبات) | D5: واحد | E5: نوع سبد | F5: توضیحات
A6: Code | B6: Product | C6: Category | D6: Unit | E6: Basket | F6: Notes
A7: PS01 | B7: پرتقال درجه ۱ — بسته‌بندی | C7: پرتقال | D7: کیلوگرم | E7: BK03 | F7: خروج خط سورتینگ
A8: PS02 | B8: پرتقال درجه ۲ — عمومی | C8: پرتقال | D8: کیلوگرم | E8: BK02
A9: PS03 | B9: نارنگی درجه ۱ — بسته‌بندی | C9: نارنگی | D9: کیلوگرم | E9: BK03
A10: PS04 | B10: نارنگی عمومی | C10: نارنگی | D10: کیلوگرم | E10: BK01
A11: PS05
A12: PS06
A13: PS07
A14: PS08
A15: PS09
A16: PS10
A17: PS11
A18: PS12
A19: PS13
A20: PS14
A21: PS15
A22: PS16
... A106: PS100

Sheet Baskets
A1: مازندشت — سورتینگ و بسته‌بندی مرکبات
A2: باغدشت، بخش مرکزی، شهرستان قائم‌شهر، استان مازندران، ایران
A3: انواع سبدها و ظروف
A4: کدها از BK01 شروع می‌شوند. ستون آخر خودکار است و در کشوی «نوع سبد» محصولات استفاده می‌شود.
A5: کد | B5: نام | C5: ظرفیت (کیلوگرم) | D5: توضیحات | E5: برچسب کشویی (خودکار)
A6: Code | B6: Name | C6: Capacity | D6: Notes | E6: Label (auto)
A7: BK01 | B7: سبد ۵ کیلویی | C7: 5 | D7: سبد پلاستیکی | E7: =IF($A7="","",$A7&" – "&IF($B7="","(بدون عنوان)",$B7))
A8: BK02 | B8: سبد ۱۰ کیلویی | C8: 10 | D8: سبد پلاستیکی | E8: =IF($A8="","",$A8&" – "&IF($B8="","(بدون عنوان)",$B8))
A9: BK03 | B9: جعبه ۱۰ کیلویی | C9: 10 | D9: کارتن | E9: =IF($A9="","",$A9&" – "&IF($B9="","(بدون عنوان)",$B9))
A10: BK04 | E10: =IF($A10="","",$A10&" – "&IF($B10="","(بدون عنوان)",$B10))
A11: BK05 | E11: =IF($A11="","",$A11&" – "&IF($B11="","(بدون عنوان)",$B11))
A12: BK06 | E12: =IF($A12="","",$A12&" – "&IF($B12="","(بدون عنوان)",$B12))
A13: BK07 | E13: =IF($A13="","",$A13&" – "&IF($B13="","(بدون عنوان)",$B13))
A14: BK08 | E14: =IF($A14="","",$A14&" – "&IF($B14="","(بدون عنوان)",$B14))
A15: BK09 | E15: =IF($A15="","",$A15&" – "&IF($B15="","(بدون عنوان)",$B15))
A16: BK10 | E16: =IF($A16="","",$A16&" – "&IF($B16="","(بدون عنوان)",$B16))
A17: BK11 | E17: =IF($A17="","",$A17&" – "&IF($B17="","(بدون عنوان)",$B17))
A18: BK12 | E18: =IF($A18="","",$A18&" – "&IF($B18="","(بدون عنوان)",$B18))
A19: BK13 | E19: =IF($A19="","",$A19&" – "&IF($B19="","(بدون عنوان)",$B19))
A20: BK14 | E20: =IF($A20="","",$A20&" – "&IF($B20="","(بدون عنوان)",$B20))
A21: BK15 | E21: =IF($A21="","",$A21&" – "&IF($B21="","(بدون عنوان)",$B21))
... A36: BK30 | E36: =IF($A36="","",$A36&" – "&IF($B36="","(بدون عنوان)",$B36))

Sheet Warehouses
A1: مازندشت — سورتینگ و بسته‌بندی مرکبات
A2: باغدشت، بخش مرکزی، شهرستان قائم‌شهر، استان مازندران، ایران
A3: انبارها
A4: کدها از W01 شروع می‌شوند.
A5: کد | B5: نام انبار | C5: موقعیت | D5: انباردار | E5: توضیحات
A6: Code | B6: Warehouse | C6: Location | D6: Keeper | E6: Notes
A7: W01 | B7: انبار اصلی (باغدشت) | C7: باغدشت | D7: E004 | E7: انبار محصول
A8: W02 | B8: سردخانه ۱ | C8: باغدشت | D8: E004
A9: W03 | B9: سایبان سورتینگ | C9: باغدشت | D9: E004 | E9: ورودی خط سورتینگ
A10: W04
A11: W05
A12: W06
A13: W07
A14: W08
A15: W09
A16: W10
A17: W11
A18: W12
A19: W13
A20: W14
A21: W15

Sheet Lists
A1: مازندشت — سورتینگ و بسته‌بندی مرکبات
A2: باغدشت، بخش مرکزی، شهرستان قائم‌شهر، استان مازندران، ایران
A3: لیست‌های عمومی (منبع کشوهای این فایل)
A5: واحد شمارش | B5: سمت‌ها | C5: دسته محصولات | D5: بله/خیر | E5: جهت
A6: Units | B6: Roles | C6: Categories | D6: Yes/No | E6: Direction
A7: کیلوگرم | B7: مدیرعامل | C7: پرتقال | D7: بله | E7: ورود
A8: جعبه | B8: حسابدار | C8: نارنگی | D8: خیر | E8: خروج
A9: سبد | B9: فروشنده | C9: لیمو
A10: تن | B10: انباردار | C10: گریپ‌فرویت
A11: عدد | B11: سرپرست خط | C11: گیلاس
B12: کارگر | C12: سایر

Sheet Help
A1: مازندشت — سورتینگ و بسته‌بندی مرکبات
A2: باغدشت، بخش مرکزی، شهرستان قائم‌شهر، استان مازندران، ایران | MAZANDASHT · CITRUS SORTING & PACKING
A3: راهنمای کل سامانه مازندشت — همه فایل‌ها، جریان داده و قواعد
A5: ۱) نقشه سامانه (۱۰ فایل — همیشه در یک پوشه)
A6: • INFO.xlsx — همین فایل مادر: تعریف همه اطلاعات پایه (حساب‌ها، گروه‌ها و زیرگروه‌های تراکنش، گروه‌های کاری، کارکنان، بانک‌ها، عملیات، محصولات، پارامترها) + همین راهنما.
A7: • Baskol.xlsx — دفتر باسکول: تنها محل ثبت ورود و خروج کالا. هر توزین (خرید، فروش، مرجوعی، انتقال) یک ردیف.
A8: • Transactions.xlsx — پول: واریز/برداشت‌های بانکی + صورت‌حساب ۱۰ بانک.
A9: • Sales.xlsx — خروجی فروش: صورت‌حساب کدمحور هر فروشنده — از باسکول و تراکنش‌ها می‌خواند.
A10: • Purchases.xlsx — خروجی خرید: گزارش کدمحور خرید هر حساب + خلاصه همه حساب‌ها — از باسکول و تراکنش‌ها می‌خواند.
A11: • Expenses.xlsx — خروجی هزینه: خلاصه و گزارش هزینه‌ها به تفکیک زیرگروه — از تراکنش‌ها می‌خواند.
A12: • Employees.xlsx — دفتر دستمزد کارکنان: ثبت دستمزد فردی و گروهی + ریز سهم اعضای هر گروه + مانده هر نفر.
A13: • Baskets.xlsx — دفتر سبد: خرید سبد از فروشنده سبد (تعداد × فی) با مانده حساب در هر سطر + کارتکس هر فروشنده + خلاصه انواع سبد.
... A48: • برای ظرفیت بیشتر (ردیف‌های ورود داده)، فرمول‌های ردیف آخر هر شیت را به پایین کپی کنید.
